Workbook

Sheet List
A1: סימול | B1: שם | C1: מחלקה | D1: תווית | E1: מספר כישלונות | F1: 1 רווחיות | G1: 2 תזרים | H1: 3 תשואה על ההון | I1: 4 מאזן | J1: 5 צמיחה | K1: 6 דילול | L1: סיבת הכישלון | M1: Risk Tier | N1: תקרת פוזיציה CORE | O1: Cheap Score | P1: רבעון זול | Q1: SMA200 עולה | R1: Cheap Score שמיש לשיטה | S1: שווי מול עצמה | T1: P/E מול חציון עצמי | U1: FCF yield | V1: ADR60 | W1: Max DD (5 שנים)
A2: =Data!A2 -> ABNB | B2: =Data!B2 -> Airbnb Inc. | C2: =Data!F2 -> STD | D2: =IF(E2=0,"CORE",IF(E2=1,"WATCH","NON-CORE")) -> CORE | E2: =COUNTIF(F2:K2,"FAIL") -> 0 | F2: =IF(C2="FIN",IF(Data!M2=Data!H2,"PASS","FAIL"),IF(AND(ISNUMBER(Data!L2),Data!L2>=Rules!$B$5,IF(Data!H2<5,Data!M2=Data!H2,Data!M2>=Rules!$B$6)),"PASS","FAIL")) -> PASS | G2: =IF(C2="FIN","n/a",IF(C2="UTIL/REIT",IF(Data!Q2=Data!H2,"PASS","FAIL"),IF(AND(ISNUMBER(Data!N2),Data!N2>0,IF(Data!H2<5,Data!P2=Data!H2,Data!P2>=Rules!$B$7)),"PASS","FAIL"))) -> PASS | H2: =IF(C2="FIN",IF(AND(ISNUMBER(Data!S2),Data!S2>=Rules!$B$15),"PASS","FAIL"),IF(AND(ISNUMBER(Data!R2),Data!R2>=Rules!$B$8),"PASS","FAIL")) -> PASS | I2: =IF(C2="FIN","n/a",IF(C2="UTIL/REIT",IF(AND(Data!U2<=Rules!$B$16,Data!V2>=Rules!$B$17),"PASS","FAIL"),IF(AND(Data!U2<=Rules!$B$9,Data!V2>=Rules!$B$10),"PASS","FAIL"))) -> PASS | J2: =IF(AND(ISNUMBER(Data!J2),ISNUMBER(Data!K2)),IF(AND(Data!J2>=Rules!$B$11,Data!K2>=Rules!$B$12),"PASS","FAIL"),"FAIL") -> PASS | K2: =IF(AND(ISNUMBER(Data!W2),ISNUMBER(Data!X2)),IF(AND(Data!W2<=Rules!$B$13,Data!X2<=Rules!$B$14),"PASS","FAIL"),"FAIL") -> PASS | L2: =IF(F2="FAIL","רווחיות; ","")&IF(G2="FAIL","תזרים; ","")&IF(H2="FAIL","תשואה על ההון; ","")&IF(I2="FAIL","מאזן; ","")&IF(J2="FAIL","צמיחה; ","")&IF(K2="FAIL","דילול; ","") | M2: HIGH | N2: =IF(M2="EXTREME",Rules!$B$23,IF(M2="HIGH",Rules!$B$22,Rules!$B$21)) -> 0.06 | O2: 31.350718 | P2: Q2 | Q2: כן | R2: =IF(Q2="כן",P2,"לא רלוונטי (SMA200 יורד)") -> Q2 | S2: =IF(NOT(ISNUMBER(T2)),"n/a",IF(AND(T2>Rules!$B$18,ISNUMBER(U2),U2<Rules!$B$19),"יקרה",IF(T2<Rules!$B$20,"זולה","הוגנת"))) -> הוגנת | T2: =Data!AA2 -> 1.2345654 | U2: =Data!AC2 -> 0.049967079 | V2: 0.0297 | W2: -0.6023
A3: =Data!A3 -> ADBE | B3: =Data!B3 -> Adobe Inc. | C3: =Data!F3 -> STD | D3: =IF(E3=0,"CORE",IF(E3=1,"WATCH","NON-CORE")) -> CORE | E3: =COUNTIF(F3:K3,"FAIL") -> 0 | F3: =IF(C3="FIN",IF(Data!M3=Data!H3,"PASS","FAIL"),IF(AND(ISNUMBER(Data!L3),Data!L3>=Rules!$B$5,IF(Data!H3<5,Data!M3=Data!H3,Data!M3>=Rules!$B$6)),"PASS","FAIL")) -> PASS | G3: =IF(C3="FIN","n/a",IF(C3="UTIL/REIT",IF(Data!Q3=Data!H3,"PASS","FAIL"),IF(AND(ISNUMBER(Data!N3),Data!N3>0,IF(Data!H3<5,Data!P3=Data!H3,Data!P3>=Rules!$B$7)),"PASS","FAIL"))) -> PASS | H3: =IF(C3="FIN",IF(AND(ISNUMBER(Data!S3),Data!S3>=Rules!$B$15),"PASS","FAIL"),IF(AND(ISNUMBER(Data!R3),Data!R3>=Rules!$B$8),"PASS","FAIL")) -> PASS | I3: =IF(C3="FIN","n/a",IF(C3="UTIL/REIT",IF(AND(Data!U3<=Rules!$B$16,Data!V3>=Rules!$B$17),"PASS","FAIL"),IF(AND(Data!U3<=Rules!$B$9,Data!V3>=Rules!$B$10),"PASS","FAIL"))) -> PASS | J3: =IF(AND(ISNUMBER(Data!J3),ISNUMBER(Data!K3)),IF(AND(Data!J3>=Rules!$B$11,Data!K3>=Rules!$B$12),"PASS","FAIL"),"FAIL") -> PASS | K3: =IF(AND(ISNUMBER(Data!W3),ISNUMBER(Data!X3)),IF(AND(Data!W3<=Rules!$B$13,Data!X3<=Rules!$B$14),"PASS","FAIL"),"FAIL") -> PASS | L3: =IF(F3="FAIL","רווחיות; ","")&IF(G3="FAIL","תזרים; ","")&IF(H3="FAIL","תשואה על ההון; ","")&IF(I3="FAIL","מאזן; ","")&IF(J3="FAIL","צמיחה; ","")&IF(K3="FAIL","דילול; ","") | M3: EXTREME | N3: =IF(M3="EXTREME",Rules!$B$23,IF(M3="HIGH",Rules!$B$22,Rules!$B$21)) -> 0.03 | O3: 53.644553 | P3: Q3 | Q3: לא | R3: =IF(Q3="כן",P3,"לא רלוונטי (SMA200 יורד)") -> לא רלוונטי (SMA200 יורד) | S3: =IF(NOT(ISNUMBER(T3)),"n/a",IF(AND(T3>Rules!$B$18,ISNUMBER(U3),U3<Rules!$B$19),"יקרה",IF(T3<Rules!$B$20,"זולה","הוגנת"))) -> זולה | T3: =Data!AA3 -> 0.31880781 | U3: =Data!AC3 -> 0.11595158 | V3: 0.0366 | W3: -0.7189
A4: =Data!A4 -> ADP | B4: =Data!B4 -> Automatic Data Processing Inc. | C4: =Data!F4 -> STD | D4: =IF(E4=0,"CORE",IF(E4=1,"WATCH","NON-CORE")) -> CORE | E4: =COUNTIF(F4:K4,"FAIL") -> 0 | F4: =IF(C4="FIN",IF(Data!M4=Data!H4,"PASS","FAIL"),IF(AND(ISNUMBER(Data!L4),Data!L4>=Rules!$B$5,IF(Data!H4<5,Data!M4=Data!H4,Data!M4>=Rules!$B$6)),"PASS","FAIL")) -> PASS | G4: =IF(C4="FIN","n/a",IF(C4="UTIL/REIT",IF(Data!Q4=Data!H4,"PASS","FAIL"),IF(AND(ISNUMBER(Data!N4),Data!N4>0,IF(Data!H4<5,Data!P4=Data!H4,Data!P4>=Rules!$B$7)),"PASS","FAIL"))) -> PASS | H4: =IF(C4="FIN",IF(AND(ISNUMBER(Data!S4),Data!S4>=Rules!$B$15),"PASS","FAIL"),IF(AND(ISNUMBER(Data!R4),Data!R4>=Rules!$B$8),"PASS","FAIL")) -> PASS | I4: =IF(C4="FIN","n/a",IF(C4="UTIL/REIT",IF(AND(Data!U4<=Rules!$B$16,Data!V4>=Rules!$B$17),"PASS","FAIL"),IF(AND(Data!U4<=Rules!$B$9,Data!V4>=Rules!$B$10),"PASS","FAIL"))) -> PASS | J4: =IF(AND(ISNUMBER(Data!J4),ISNUMBER(Data!K4)),IF(AND(Data!J4>=Rules!$B$11,Data!K4>=Rules!$B$12),"PASS","FAIL"),"FAIL") -> PASS | K4: =IF(AND(ISNUMBER(Data!W4),ISNUMBER(Data!X4)),IF(AND(Data!W4<=Rules!$B$13,Data!X4<=Rules!$B$14),"PASS","FAIL"),"FAIL") -> PASS | L4: =IF(F4="FAIL","רווחיות; ","")&IF(G4="FAIL","תזרים; ","")&IF(H4="FAIL","תשואה על ההון; ","")&IF(I4="FAIL","מאזן; ","")&IF(J4="FAIL","צמיחה; ","")&IF(K4="FAIL","דילול; ","") | M4: MEDIUM | N4: =IF(M4="EXTREME",Rules!$B$23,IF(M4="HIGH",Rules!$B$22,Rules!$B$21)) -> 0.1 | O4: 44.591367 | P4: Q2 | Q4: כן | R4: =IF(Q4="כן",P4,"לא רלוונטי (SMA200 יורד)") -> Q2 | S4: =IF(NOT(ISNUMBER(T4)),"n/a",IF(AND(T4>Rules!$B$18,ISNUMBER(U4),U4<Rules!$B$19),"יקרה",IF(T4<Rules!$B$20,"זולה","הוגנת"))) -> הוגנת | T4: =Data!AA4 -> 0.94277549 | U4: =Data!AC4 -> 0.045209355 | V4: 0.0222 | W4: -0.4223
A5: =Data!A5 -> ANET | B5: =Data!B5 -> Arista Networks Inc. | C5: =Data!F5 -> STD | D5: =IF(E5=0,"CORE",IF(E5=1,"WATCH","NON-CORE")) -> CORE | E5: =COUNTIF(F5:K5,"FAIL") -> 0 | F5: =IF(C5="FIN",IF(Data!M5=Data!H5,"PASS","FAIL"),IF(AND(ISNUMBER(Data!L5),Data!L5>=Rules!$B$5,IF(Data!H5<5,Data!M5=Data!H5,Data!M5>=Rules!$B$6)),"PASS","FAIL")) -> PASS | G5: =IF(C5="FIN","n/a",IF(C5="UTIL/REIT",IF(Data!Q5=Data!H5,"PASS","FAIL"),IF(AND(ISNUMBER(Data!N5),Data!N5>0,IF(Data!H5<5,Data!P5=Data!H5,Data!P5>=Rules!$B$7)),"PASS","FAIL"))) -> PASS | H5: =IF(C5="FIN",IF(AND(ISNUMBER(Data!S5),Data!S5>=Rules!$B$15),"PASS","FAIL"),IF(AND(ISNUMBER(Data!R5),Data!R5>=Rules!$B$8),"PASS","FAIL")) -> PASS | I5: =IF(C5="FIN","n/a",IF(C5="UTIL/REIT",IF(AND(Data!U5<=Rules!$B$16,Data!V5>=Rules!$B$17),"PASS","FAIL"),IF(AND(Data!U5<=Rules!$B$9,Data!V5>=Rules!$B$10),"PASS","FAIL"))) -> PASS | J5: =IF(AND(ISNUMBER(Data!J5),ISNUMBER(Data!K5)),IF(AND(Data!J5>=Rules!$B$11,Data!K5>=Rules!$B$12),"PASS","FAIL"),"FAIL") -> PASS | K5: =IF(AND(ISNUMBER(Data!W5),ISNUMBER(Data!X5)),IF(AND(Data!W5<=Rules!$B$13,Data!X5<=Rules!$B$14),"PASS","FAIL"),"FAIL") -> PASS | L5: =IF(F5="FAIL","רווחיות; ","")&IF(G5="FAIL","תזרים; ","")&IF(H5="FAIL","תשואה על ההון; ","")&IF(I5="FAIL","מאזן; ","")&IF(J5="FAIL","צמיחה; ","")&IF(K5="FAIL","דילול; ","") | M5: EXTREME | N5: =IF(M5="EXTREME",Rules!$B$23,IF(M5="HIGH",Rules!$B$22,Rules!$B$21)) -> 0.03 | O5: 27.546126 | P5: Q2 | Q5: כן | R5: =IF(Q5="כן",P5,"לא רלוונטי (SMA200 יורד)") -> Q2 | S5: =IF(NOT(ISNUMBER(T5)),"n/a",IF(AND(T5>Rules!$B$18,ISNUMBER(U5),U5<Rules!$B$19),"יקרה",IF(T5<Rules!$B$20,"זולה","הוגנת"))) -> יקרה | T5: =Data!AA5 -> 1.3988264 | U5: =Data!AC5 -> 0.019414865 | V5: 0.0422 | W5: -0.5043
A6: =Data!A6 -> APH | B6: =Data!B6 -> Amphenol Corp. | C6: =Data!F6 -> STD | D6: =IF(E6=0,"CORE",IF(E6=1,"WATCH","NON-CORE")) -> CORE | E6: =COUNTIF(F6:K6,"FAIL") -> 0 | F6: =IF(C6="FIN",IF(Data!M6=Data!H6,"PASS","FAIL"),IF(AND(ISNUMBER(Data!L6),Data!L6>=Rules!$B$5,IF(Data!H6<5,Data!M6=Data!H6,Data!M6>=Rules!$B$6)),"PASS","FAIL")) -> PASS | G6: =IF(C6="FIN","n/a",IF(C6="UTIL/REIT",IF(Data!Q6=Data!H6,"PASS","FAIL"),IF(AND(ISNUMBER(Data!N6),Data!N6>0,IF(Data!H6<5,Data!P6=Data!H6,Data!P6>=Rules!$B$7)),"PASS","FAIL"))) -> PASS | H6: =IF(C6="FIN",IF(AND(ISNUMBER(Data!S6),Data!S6>=Rules!$B$15),"PASS","FAIL"),IF(AND(ISNUMBER(Data!R6),Data!R6>=Rules!$B$8),"PASS","FAIL")) -> PASS | I6: =IF(C6="FIN","n/a",IF(C6="UTIL/REIT",IF(AND(Data!U6<=Rules!$B$16,Data!V6>=Rules!$B$17),"PASS","FAIL"),IF(AND(Data!U6<=Rules!$B$9,Data!V6>=Rules!$B$10),"PASS","FAIL"))) -> PASS | J6: =IF(AND(ISNUMBER(Data!J6),ISNUMBER(Data!K6)),IF(AND(Data!J6>=Rules!$B$11,Data!K6>=Rules!$B$12),"PASS","FAIL"),"FAIL") -> PASS | K6: =IF(AND(ISNUMBER(Data!W6),ISNUMBER(Data!X6)),IF(AND(Data!W6<=Rules!$B$13,Data!X6<=Rules!$B$14),"PASS","FAIL"),"FAIL") -> PASS | L6: =IF(F6="FAIL","רווחיות; ","")&IF(G6="FAIL","תזרים; ","")&IF(H6="FAIL","תשואה על ההון; ","")&IF(I6="FAIL","מאזן; ","")&IF(J6="FAIL","צמיחה; ","")&IF(K6="FAIL","דילול; ","") | M6: HIGH | N6: =IF(M6="EXTREME",Rules!$B$23,IF(M6="HIGH",Rules!$B$22,Rules!$B$21)) -> 0.06 | O6: 45.708087 | P6: Q2 | Q6: כן | R6: =IF(Q6="כן",P6,"לא רלוונטי (SMA200 יורד)") -> Q2 | S6: =IF(NOT(ISNUMBER(T6)),"n/a",IF(AND(T6>Rules!$B$18,ISNUMBER(U6),U6<Rules!$B$19),"יקרה",IF(T6<Rules!$B$20,"זולה","הוגנת"))) -> הוגנת | T6: =Data!AA6 -> 1.2297439 | U6: =Data!AC6 -> 0.022177829 | V6: 0.0335 | W6: -0.2887
A7: =Data!A7 -> APP | B7: =Data!B7 -> AppLovin Corp. | C7: =Data!F7 -> STD | D7: =IF(E7=0,"CORE",IF(E7=1,"WATCH","NON-CORE")) -> CORE | E7: =COUNTIF(F7:K7,"FAIL") -> 0 | F7: =IF(C7="FIN",IF(Data!M7=Data!H7,"PASS","FAIL"),IF(AND(ISNUMBER(Data!L7),Data!L7>=Rules!$B$5,IF(Data!H7<5,Data!M7=Data!H7,Data!M7>=Rules!$B$6)),"PASS","FAIL")) -> PASS | G7: =IF(C7="FIN","n/a",IF(C7="UTIL/REIT",IF(Data!Q7=Data!H7,"PASS","FAIL"),IF(AND(ISNUMBER(Data!N7),Data!N7>0,IF(Data!H7<5,Data!P7=Data!H7,Data!P7>=Rules!$B$7)),"PASS","FAIL"))) -> PASS | H7: =IF(C7="FIN",IF(AND(ISNUMBER(Data!S7),Data!S7>=Rules!$B$15),"PASS","FAIL"),IF(AND(ISNUMBER(Data!R7),Data!R7>=Rules!$B$8),"PASS","FAIL")) -> PASS | I7: =IF(C7="FIN","n/a",IF(C7="UTIL/REIT",IF(AND(Data!U7<=Rules!$B$16,Data!V7>=Rules!$B$17),"PASS","FAIL"),IF(AND(Data!U7<=Rules!$B$9,Data!V7>=Rules!$B$10),"PASS","FAIL"))) -> PASS | J7: =IF(AND(ISNUMBER(Data!J7),ISNUMBER(Data!K7)),IF(AND(Data!J7>=Rules!$B$11,Data!K7>=Rules!$B$12),"PASS","FAIL"),"FAIL") -> PASS | K7: =IF(AND(ISNUMBER(Data!W7),ISNUMBER(Data!X7)),IF(AND(Data!W7<=Rules!$B$13,Data!X7<=Rules!$B$14),"PASS","FAIL"),"FAIL") -> PASS | L7: =IF(F7="FAIL","רווחיות; ","")&IF(G7="FAIL","תזרים; ","")&IF(H7="FAIL","תשואה על ההון; ","")&IF(I7="FAIL","מאזן; ","")&IF(J7="FAIL","צמיחה; ","")&IF(K7="FAIL","דילול; ","") | M7: EXTREME | N7: =IF(M7="EXTREME",Rules!$B$23,IF(M7="HIGH",Rules!$B$22,Rules!$B$21)) -> 0.03 | O7: 84.490415 | P7: Q4 | Q7: לא | R7: =IF(Q7="כן",P7,"לא רלוונטי (SMA200 יורד)") -> לא רלוונטי (SMA200 יורד) | S7: =IF(NOT(ISNUMBER(T7)),"n/a",IF(AND(T7>Rules!$B$18,ISNUMBER(U7),U7<Rules!$B$19),"יקרה",IF(T7<Rules!$B$20,"זולה","הוגנת"))) -> זולה | T7: =Data!AA7 -> 0.30107134 | U7: =Data!AC7 -> 0.049444747 | V7: 0.0464 | W7: -0.9195
A8: =Data!A8 -> ASML | B8: =Data!B8 -> ASML Holding N.V. | C8: =Data!F8 -> STD | D8: =IF(E8=0,"CORE",IF(E8=1,"WATCH","NON-CORE")) -> CORE | E8: =COUNTIF(F8:K8,"FAIL") -> 0 | F8: =IF(C8="FIN",IF(Data!M8=Data!H8,"PASS","FAIL"),IF(AND(ISNUMBER(Data!L8),Data!L8>=Rules!$B$5,IF(Data!H8<5,Data!M8=Data!H8,Data!M8>=Rules!$B$6)),"PASS","FAIL")) -> PASS | G8: =IF(C8="FIN","n/a",IF(C8="UTIL/REIT",IF(Data!Q8=Data!H8,"PASS","FAIL"),IF(AND(ISNUMBER(Data!N8),Data!N8>0,IF(Data!H8<5,Data!P8=Data!H8,Data!P8>=Rules!$B$7)),"PASS","FAIL"))) -> PASS | H8: =IF(C8="FIN",IF(AND(ISNUMBER(Data!S8),Data!S8>=Rules!$B$15),"PASS","FAIL"),IF(AND(ISNUMBER(Data!R8),Data!R8>=Rules!$B$8),"PASS","FAIL")) -> PASS | I8: =IF(C8="FIN","n/a",IF(C8="UTIL/REIT",IF(AND(Data!U8<=Rules!$B$16,Data!V8>=Rules!$B$17),"PASS","FAIL"),IF(AND(Data!U8<=Rules!$B$9,Data!V8>=Rules!$B$10),"PASS","FAIL"))) -> PASS | J8: =IF(AND(ISNUMBER(Data!J8),ISNUMBER(Data!K8)),IF(AND(Data!J8>=Rules!$B$11,Data!K8>=Rules!$B$12),"PASS","FAIL"),"FAIL") -> PASS | K8: =IF(AND(ISNUMBER(Data!W8),ISNUMBER(Data!X8)),IF(AND(Data!W8<=Rules!$B$13,Data!X8<=Rules!$B$14),"PASS","FAIL"),"FAIL") -> PASS | L8: =IF(F8="FAIL","רווחיות; ","")&IF(G8="FAIL","תזרים; ","")&IF(H8="FAIL","תשואה על ההון; ","")&IF(I8="FAIL","מאזן; ","")&IF(J8="FAIL","צמיחה; ","")&IF(K8="FAIL","דילול; ","") | M8: HIGH | N8: =IF(M8="EXTREME",Rules!$B$23,IF(M8="HIGH",Rules!$B$22,Rules!$B$21)) -> 0.06 | O8: 40.730664 | P8: Q2 | Q8: כן | R8: =IF(Q8="כן",P8,"לא רלוונטי (SMA200 יורד)") -> Q2 | S8: =IF(NOT(ISNUMBER(T8)),"n/a",IF(AND(T8>Rules!$B$18,ISNUMBER(U8),U8<Rules!$B$19),"יקרה",IF(T8<Rules!$B$20,"זולה","הוגנת"))) -> יקרה | T8: =Data!AA8 -> 1.5359206 | U8: =Data!AC8 -> 0.016987946 | V8: 0.0281 | W8: -0.5684
A9: =Data!A9 -> AXP | B9: =Data!B9 -> American Express Co. | C9: =Data!F9 -> FIN | D9: =IF(E9=0,"CORE",IF(E9=1,"WATCH","NON-CORE")) -> CORE | E9: =COUNTIF(F9:K9,"FAIL") -> 0 | F9: =IF(C9="FIN",IF(Data!M9=Data!H9,"PASS","FAIL"),IF(AND(ISNUMBER(Data!L9),Data!L9>=Rules!$B$5,IF(Data!H9<5,Data!M9=Data!H9,Data!M9>=Rules!$B$6)),"PASS","FAIL")) -> PASS | G9: =IF(C9="FIN","n/a",IF(C9="UTIL/REIT",IF(Data!Q9=Data!H9,"PASS","FAIL"),IF(AND(ISNUMBER(Data!N9),Data!N9>0,IF(Data!H9<5,Data!P9=Data!H9,Data!P9>=Rules!$B$7)),"PASS","FAIL"))) -> n/a | H9: =IF(C9="FIN",IF(AND(ISNUMBER(Data!S9),Data!S9>=Rules!$B$15),"PASS","FAIL"),IF(AND(ISNUMBER(Data!R9),Data!R9>=Rules!$B$8),"PASS","FAIL")) -> PASS | I9: =IF(C9="FIN","n/a",IF(C9="UTIL/REIT",IF(AND(Data!U9<=Rules!$B$16,Data!V9>=Rules!$B$17),"PASS","FAIL"),IF(AND(Data!U9<=Rules!$B$9,Data!V9>=Rules!$B$10),"PASS","FAIL"))) -> n/a | J9: =IF(AND(ISNUMBER(Data!J9),ISNUMBER(Data!K9)),IF(AND(Data!J9>=Rules!$B$11,Data!K9>=Rules!$B$12),"PASS","FAIL"),"FAIL") -> PASS | K9: =IF(AND(ISNUMBER(Data!W9),ISNUMBER(Data!X9)),IF(AND(Data!W9<=Rules!$B$13,Data!X9<=Rules!$B$14),"PASS","FAIL"),"FAIL") -> PASS | L9: =IF(F9="FAIL","רווחיות; ","")&IF(G9="FAIL","תזרים; ","")&IF(H9="FAIL","תשואה על ההון; ","")&IF(I9="FAIL","מאזן; ","")&IF(J9="FAIL","צמיחה; ","")&IF(K9="FAIL","דילול; ","") | M9: MEDIUM | N9: =IF(M9="EXTREME",Rules!$B$23,IF(M9="HIGH",Rules!$B$22,Rules!$B$21)) -> 0.1 | O9: 91.516139 | P9: Q4 | Q9: לא | R9: =IF(Q9="כן",P9,"לא רלוונטי (SMA200 יורד)") -> לא רלוונטי (SMA200 יורד) | S9: =IF(NOT(ISNUMBER(T9)),"n/a",IF(AND(T9>Rules!$B$18,ISNUMBER(U9),U9<Rules!$B$19),"יקרה",IF(T9<Rules!$B$20,"זולה","הוגנת"))) -> הוגנת | T9: =Data!AA9 -> 1.1324746 | U9: =Data!AC9 -> 0.072181816 | V9: 0.018 | W9: -0.3198
A10: =Data!A10 -> BAC | B10: =Data!B10 -> Bank of America Corp. | C10: =Data!F10 -> FIN | D10: =IF(E10=0,"CORE",IF(E10=1,"WATCH","NON-CORE")) -> CORE | E10: =COUNTIF(F10:K10,"FAIL") -> 0 | F10: =IF(C10="FIN",IF(Data!M10=Data!H10,"PASS","FAIL"),IF(AND(ISNUMBER(Data!L10),Data!L10>=Rules!$B$5,IF(Data!H10<5,Data!M10=Data!H10,Data!M10>=Rules!$B$6)),"PASS","FAIL")) -> PASS | G10: =IF(C10="FIN","n/a",IF(C10="UTIL/REIT",IF(Data!Q10=Data!H10,"PASS","FAIL"),IF(AND(ISNUMBER(Data!N10),Data!N10>0,IF(Data!H10<5,Data!P10=Data!H10,Data!P10>=Rules!$B$7)),"PASS","FAIL"))) -> n/a | H10: =IF(C10="FIN",IF(AND(ISNUMBER(Data!S10),Data!S10>=Rules!$B$15),"PASS","FAIL"),IF(AND(ISNUMBER(Data!R10),Data!R10>=Rules!$B$8),"PASS","FAIL")) -> PASS | I10: =IF(C10="FIN","n/a",IF(C10="UTIL/REIT",IF(AND(Data!U10<=Rules!$B$16,Data!V10>=Rules!$B$17),"PASS","FAIL"),IF(AND(Data!U10<=Rules!$B$9,Data!V10>=Rules!$B$10),"PASS","FAIL"))) -> n/a | J10: =IF(AND(ISNUMBER(Data!J10),ISNUMBER(Data!K10)),IF(AND(Data!J10>=Rules!$B$11,Data!K10>=Rules!$B$12),"PASS","FAIL"),"FAIL") -> PASS | K10: =IF(AND(ISNUMBER(Data!W10),ISNUMBER(Data!X10)),IF(AND(Data!W10<=Rules!$B$13,Data!X10<=Rules!$B$14),"PASS","FAIL"),"FAIL") -> PASS | L10: =IF(F10="FAIL","רווחיות; ","")&IF(G10="FAIL","תזרים; ","")&IF(H10="FAIL","תשואה על ההון; ","")&IF(I10="FAIL","מאזן; ","")&IF(J10="FAIL","צמיחה; ","")&IF(K10="FAIL","דילול; ","") | M10: MEDIUM | N10: =IF(M10="EXTREME",Rules!$B$23,IF(M10="HIGH",Rules!$B$22,Rules!$B$21)) -> 0.1 | O10: 74.53075 | P10: Q3 | Q10: כן | R10: =IF(Q10="כן",P10,"לא רלוונטי (SMA200 יורד)") -> Q3 | S10: =IF(NOT(ISNUMBER(T10)),"n/a",IF(AND(T10>Rules!$B$18,ISNUMBER(U10),U10<Rules!$B$19),"יקרה",IF(T10<Rules!$B$20,"זולה","הוגנת"))) -> הוגנת | T10: =Data!AA10 -> 0.99770185 | U10: =Data!AC10 -> 0.24552378 | V10: 0.0185 | W10: -0.4903
A11: =Data!A11 -> BKNG | B11: =Data!B11 -> Booking Holdings Inc. | C11: =Data!F11 -> STD | D11: =IF(E11=0,"CORE",IF(E11=1,"WATCH","NON-CORE")) -> CORE | E11: =COUNTIF(F11:K11,"FAIL") -> 0 | F11: =IF(C11="FIN",IF(Data!M11=Data!H11,"PASS","FAIL"),IF(AND(ISNUMBER(Data!L11),Data!L11>=Rules!$B$5,IF(Data!H11<5,Data!M11=Data!H11,Data!M11>=Rules!$B$6)),"PASS","FAIL")) -> PASS | G11: =IF(C11="FIN","n/a",IF(C11="UTIL/REIT",IF(Data!Q11=Data!H11,"PASS","FAIL"),IF(AND(ISNUMBER(Data!N11),Data!N11>0,IF(Data!H11<5,Data!P11=Data!H11,Data!P11>=Rules!$B$7)),"PASS","FAIL"))) -> PASS | H11: =IF(C11="FIN",IF(AND(ISNUMBER(Data!S11),Data!S11>=Rules!$B$15),"PASS","FAIL"),IF(AND(ISNUMBER(Data!R11),Data!R11>=Rules!$B$8),"PASS","FAIL")) -> PASS | I11: =IF(C11="FIN","n/a",IF(C11="UTIL/REIT",IF(AND(Data!U11<=Rules!$B$16,Data!V11>=Rules!$B$17),"PASS","FAIL"),IF(AND(Data!U11<=Rules!$B$9,Data!V11>=Rules!$B$10),"PASS","FAIL"))) -> PASS | J11: =IF(AND(ISNUMBER(Data!J11),ISNUMBER(Data!K11)),IF(AND(Data!J11>=Rules!$B$11,Data!K11>=Rules!$B$12),"PASS","FAIL"),"FAIL") -> PASS | K11: =IF(AND(ISNUMBER(Data!W11),ISNUMBER(Data!X11)),IF(AND(Data!W11<=Rules!$B$13,Data!X11<=Rules!$B$14),"PASS","FAIL"),"FAIL") -> PASS | L11: =IF(F11="FAIL","רווחיות; ","")&IF(G11="FAIL","תזרים; ","")&IF(H11="FAIL","תשואה על ההון; ","")&IF(I11="FAIL","מאזן; ","")&IF(J11="FAIL","צמיחה; ","")&IF(K11="FAIL","דילול; ","") | M11: HIGH | N11: =IF(M11="EXTREME",Rules!$B$23,IF(M11="HIGH",Rules!$B$22,Rules!$B$21)) -> 0.06 | O11: 87.224825 | P11: Q4 | Q11: לא | R11: =IF(Q11="כן",P11,"לא רלוונטי (SMA200 יורד)") -> לא רלוונטי (SMA200 יורד) | S11: =IF(NOT(ISNUMBER(T11)),"n/a",IF(AND(T11>Rules!$B$18,ISNUMBER(U11),U11<Rules!$B$19),"יקרה",IF(T11<Rules!$B$20,"זולה","הוגנת"))) -> זולה | T11: =Data!AA11 -> 0.5847194 | U11: =Data!AC11 -> 0.07795292 | V11: 0.0328 | W11: -0.3952
A12: =Data!A12 -> BSX | B12: =Data!B12 -> Boston Scientific Corp. | C12: =Data!F12 -> STD | D12: =IF(E12=0,"CORE",IF(E12=1,"WATCH","NON-CORE")) -> CORE | E12: =COUNTIF(F12:K12,"FAIL") -> 0 | F12: =IF(C12="FIN",IF(Data!M12=Data!H12,"PASS","FAIL"),IF(AND(ISNUMBER(Data!L12),Data!L12>=Rules!$B$5,IF(Data!H12<5,Data!M12=Data!H12,Data!M12>=Rules!$B$6)),"PASS","FAIL")) -> PASS | G12: =IF(C12="FIN","n/a",IF(C12="UTIL/REIT",IF(Data!Q12=Data!H12,"PASS","FAIL"),IF(AND(ISNUMBER(Data!N12),Data!N12>0,IF(Data!H12<5,Data!P12=Data!H12,Data!P12>=Rules!$B$7)),"PASS","FAIL"))) -> PASS | H12: =IF(C12="FIN",IF(AND(ISNUMBER(Data!S12),Data!S12>=Rules!$B$15),"PASS","FAIL"),IF(AND(ISNUMBER(Data!R12),Data!R12>=Rules!$B$8),"PASS","FAIL")) -> PASS | I12: =IF(C12="FIN","n/a",IF(C12="UTIL/REIT",IF(AND(Data!U12<=Rules!$B$16,Data!V12>=Rules!$B$17),"PASS","FAIL"),IF(AND(Data!U12<=Rules!$B$9,Data!V12>=Rules!$B$10),"PASS","FAIL"))) -> PASS | J12: =IF(AND(ISNUMBER(Data!J12),ISNUMBER(Data!K12)),IF(AND(Data!J12>=Rules!$B$11,Data!K12>=Rules!$B$12),"PASS","FAIL"),"FAIL") -> PASS | K12: =IF(AND(ISNUMBER(Data!W12),ISNUMBER(Data!X12)),IF(AND(Data!W12<=Rules!$B$13,Data!X12<=Rules!$B$14),"PASS","FAIL"),"FAIL") -> PASS | L12: =IF(F12="FAIL","רווחיות; ","")&IF(G12="FAIL","תזרים; ","")&IF(H12="FAIL","תשואה על ההון; ","")&IF(I12="FAIL","מאזן; ","")&IF(J12="FAIL","צמיחה; ","")&IF(K12="FAIL","דילול; ","") | M12: HIGH | N12: =IF(M12="EXTREME",Rules!$B$23,IF(M12="HIGH",Rules!$B$22,Rules!$B$21)) -> 0.06 | O12: 93.817662 | P12: Q4 | Q12: לא | R12: =IF(Q12="כן",P12,"לא רלוונטי (SMA200 יורד)") -> לא רלוונטי (SMA200 יורד) | S12: =IF(NOT(ISNUMBER(T12)),"n/a",IF(AND(T12>Rules!$B$18,ISNUMBER(U12),U12<Rules!$B$19),"יקרה",IF(T12<Rules!$B$20,"זולה","הוגנת"))) -> זולה | T12: =Data!AA12 -> 0.28268485 | U12: =Data!AC12 -> 0.056710704 | V12: 0.0312 | W12: -0.6058
A13: =Data!A13 -> CAT | B13: =Data!B13 -> Caterpillar Inc. | C13: =Data!F13 -> STD | D13: =IF(E13=0,"CORE",IF(E13=1,"WATCH","NON-CORE")) -> CORE | E13: =COUNTIF(F13:K13,"FAIL") -> 0 | F13: =IF(C13="FIN",IF(Data!M13=Data!H13,"PASS","FAIL"),IF(AND(ISNUMBER(Data!L13),Data!L13>=Rules!$B$5,IF(Data!H13<5,Data!M13=Data!H13,Data!M13>=Rules!$B$6)),"PASS","FAIL")) -> PASS | G13: =IF(C13="FIN","n/a",IF(C13="UTIL/REIT",IF(Data!Q13=Data!H13,"PASS","FAIL"),IF(AND(ISNUMBER(Data!N13),Data!N13>0,IF(Data!H13<5,Data!P13=Data!H13,Data!P13>=Rules!$B$7)),"PASS","FAIL"))) -> PASS | H13: =IF(C13="FIN",IF(AND(ISNUMBER(Data!S13),Data!S13>=Rules!$B$15),"PASS","FAIL"),IF(AND(ISNUMBER(Data!R13),Data!R13>=Rules!$B$8),"PASS","FAIL")) -> PASS | I13: =IF(C13="FIN","n/a",IF(C13="UTIL/REIT",IF(AND(Data!U13<=Rules!$B$16,Data!V13>=Rules!$B$17),"PASS","FAIL"),IF(AND(Data!U13<=Rules!$B$9,Data!V13>=Rules!$B$10),"PASS","FAIL"))) -> PASS | J13: =IF(AND(ISNUMBER(Data!J13),ISNUMBER(Data!K13)),IF(AND(Data!J13>=Rules!$B$11,Data!K13>=Rules!$B$12),"PASS","FAIL"),"FAIL") -> PASS | K13: =IF(AND(ISNUMBER(Data!W13),ISNUMBER(Data!X13)),IF(AND(Data!W13<=Rules!$B$13,Data!X13<=Rules!$B$14),"PASS","FAIL"),"FAIL") -> PASS | L13: =IF(F13="FAIL","רווחיות; ","")&IF(G13="FAIL","תזרים; ","")&IF(H13="FAIL","תשואה על ההון; ","")&IF(I13="FAIL","מאזן; ","")&IF(J13="FAIL","צמיחה; ","")&IF(K13="FAIL","דילול; ","") | M13: HIGH | N13: =IF(M13="EXTREME",Rules!$B$23,IF(M13="HIGH",Rules!$B$22,Rules!$B$21)) -> 0.06 | O13: 88.302667 | P13: Q4 | Q13: כן | R13: =IF(Q13="כן",P13,"לא רלוונטי (SMA200 יורד)") -> Q4 | S13: =IF(NOT(ISNUMBER(T13)),"n/a",IF(AND(T13>Rules!$B$18,ISNUMBER(U13),U13<Rules!$B$19),"יקרה",IF(T13<Rules!$B$20,"זולה","הוגנת"))) -> הוגנת | T13: =Data!AA13 -> 1.9175279 | U13: =Data!AC13 -> 0.024872785 | V13: 0.0302 | W13: -0.3428
... A121: =Data!A121 -> XOM | B121: =Data!B121 -> ExxonMobil Holdings Corp. | C121: =Data!F121 -> STD | D121: =IF(E121=0,"CORE",IF(E121=1,"WATCH","NON-CORE")) -> NON-CORE | E121: =COUNTIF(F121:K121,"FAIL") -> 2 | F121: =IF(C121="FIN",IF(Data!M121=Data!H121,"PASS","FAIL"),IF(AND(ISNUMBER(Data!L121),Data!L121>=Rules!$B$5,IF(Data!H121<5,Data!M121=Data!H121,Data!M121>=Rules!$B$6)),"PASS","FAIL")) -> PASS | G121: =IF(C121="FIN","n/a",IF(C121="UTIL/REIT",IF(Data!Q121=Data!H121,"PASS","FAIL"),IF(AND(ISNUMBER(Data!N121),Data!N121>0,IF(Data!H121<5,Data!P121=Data!H121,Data!P121>=Rules!$B$7)),"PASS","FAIL"))) -> PASS | H121: =IF(C121="FIN",IF(AND(ISNUMBER(Data!S121),Data!S121>=Rules!$B$15),"PASS","FAIL"),IF(AND(ISNUMBER(Data!R121),Data!R121>=Rules!$B$8),"PASS","FAIL")) -> FAIL | I121: =IF(C121="FIN","n/a",IF(C121="UTIL/REIT",IF(AND(Data!U121<=Rules!$B$16,Data!V121>=Rules!$B$17),"PASS","FAIL"),IF(AND(Data!U121<=Rules!$B$9,Data!V121>=Rules!$B$10),"PASS","FAIL"))) -> PASS | J121: =IF(AND(ISNUMBER(Data!J121),ISNUMBER(Data!K121)),IF(AND(Data!J121>=Rules!$B$11,Data!K121>=Rules!$B$12),"PASS","FAIL"),"FAIL") -> FAIL | K121: =IF(AND(ISNUMBER(Data!W121),ISNUMBER(Data!X121)),IF(AND(Data!W121<=Rules!$B$13,Data!X121<=Rules!$B$14),"PASS","FAIL"),"FAIL") -> PASS | L121: =IF(F121="FAIL","רווחיות; ","")&IF(G121="FAIL","תזרים; ","")&IF(H121="FAIL","תשואה על ההון; ","")&IF(I121="FAIL","מאזן; ","")&IF(J121="FAIL","צמיחה; ","")&IF(K121="FAIL","דילול; ","") -> תשואה על ההון; צמיחה; | M121: MEDIUM | N121: =IF(M121="EXTREME",Rules!$B$23,IF(M121="HIGH",Rules!$B$22,Rules!$B$21)) -> 0.1 | O121: 32.552552 | P121: Q2 | Q121: כן | R121: =IF(Q121="כן",P121,"לא רלוונטי (SMA200 יורד)") -> Q2 | S121: =IF(NOT(ISNUMBER(T121)),"n/a",IF(AND(T121>Rules!$B$18,ISNUMBER(U121),U121<Rules!$B$19),"יקרה",IF(T121<Rules!$B$20,"זולה","הוגנת"))) -> הוגנת | T121: =Data!AA121 -> 1.9698679 | U121: =Data!AC121 -> 0.042559882 | V121: 0.0199 | W121: -0.2068
A123: תווית ושווי מחושבים בנוסחאות מגיליונות Data ו־Rules. Cheap Score, Risk Tier, ADR60 ו־Max DD מה־DB שלנו נכון ל־30.9.2026. התווית היא סינון מכני בלבד — WATCH דורש קריאה של הסיבה; גם CORE לא בוחן חפיר תחרותי, הנהלה או תחזיות.

Sheet Rules
A1: כללי סינון CORE — הוקפאו 13.10.2026 לפני ניקוד החברות
A2: ספים (כחול = קלט). שינוי ספים משנה את התוויות ברשימה — לשימוש "מה אם" בלבד; הכללים הרשמיים הם הערכים האלה.
A4: סף | B4: ערך
A5: שולי רווח תפעולי מינימליים (STD, UTIL) | B5: 0.1
A6: מספר שנים מינימלי עם רווח נקי חיובי מתוך 5 | B6: 4
A7: מספר שנים מינימלי עם FCF חיובי מתוך 5 | B7: 4
A8: ROIC מינימלי (STD, UTIL) | B8: 0.1
A9: חוב נטו / EBITDA מקסימלי (STD) | B9: 3
A10: כיסוי ריבית מינימלי (STD) | B10: 5
A11: צמיחת הכנסות שנתית ממוצעת 3 שנים מינימלית | B11: 0.03
A12: ירידת הכנסות מקסימלית בשנה האחרונה | B12: -0.05
A13: גידול מקסימלי במספר המניות ב־3 שנים (דילול) | B13: 0.05
A14: תגמול במניות / הכנסות מקסימלי | B14: 0.15
A15: ROE מינימלי (FIN) | B15: 0.1
A16: חוב נטו / EBITDA מקסימלי (UTIL/REIT) | B16: 6
... A23: תקרת פוזיציית CORE — EXTREME | B23: 0.03
A25: מחלקות: FIN = בנקים, ברוקרים, ביטוח, מנהלי נכסים, בורסת קריפטו (JPM BAC WFC C GS MS SCHW SOFI HOOD AXP CB PGR BRK-B BLK BX KKR COIN). UTIL/REIT = DUK SO NEE PLD AMT. STD = כל השאר.
A26: 1. רווחיות — STD/UTIL: שולי רווח תפעולי בשנה האחרונה ≥ הסף, ורווח נקי חיובי ב־4 מתוך 5 שנים (בכל השנים אם יש פחות מ־5). FIN: רווח נקי חיובי בכל השנים.
A27: 2. תזרים — STD: FCF חיובי בשנה האחרונה וב־4 מתוך 5 שנים. UTIL/REIT: תזרים מפעילות חיובי בכל השנים (ההשקעות שלהן גדולות במבנה). FIN: לא רלוונטי.
A28: 3. תשואה על ההון — STD/UTIL: ROIC = הגבוה מבין ROIC של הספק (TTM) לבין רווח תפעולי × 0.79 / (חוב + הון − מזומן). FIN: רווח נקי / הון.
A29: 4. מאזן — STD: חוב נטו / EBITDA ≤ 3 (מזומן נטו עובר) וכיסוי ריבית ≥ 5. UTIL/REIT: ≤ 6 ו־≥ 2. FIN: לא רלוונטי.
A30: 5. צמיחה — צמיחת הכנסות שנתית ממוצעת ב־3 השנים האחרונות ≥ 3%, וההכנסות בשנה האחרונה לא ירדו ביותר מ־5%.
A31: 6. דילול — מספר המניות לא גדל ביותר מ־5% ב־3 שנים, ותגמול במניות ≤ 15% מההכנסות.
A32: תווית: CORE = עברה את כל 6. WATCH = נכשלה באחד — דורשת קריאה אנושית של הסיבה לפני שתהיה CORE. NON-CORE = נכשלה ב־2 ומעלה.
A33: שווי (מידע בלבד, לא משנה את התווית): P/E נוכחי חלקי החציון של ה־P/E השנתי של החברה עצמה.
A34: Cheap Score (מה־DB שלנו, נכון ל־30.9.2026): לפי NEW_PROTOCOL. נבדק היסטורית רק כש־SMA200 עולה; כשהוא יורד — מחוץ לתנאי הבדיקה, ולכן מסומן "לא רלוונטי".
A35: מגבלות: הספים לא נבדקו היסטורית (אין נתוני דוחות point-in-time) — זה מסנן איכות, לא טענה ל־edge. תחזיות אנליסטים לרוב על בסיס מותאם (לא GAAP) ולכן מוצגות בלבד. TSM בדולר טייוואני ו־ASML באירו — היחסים לא מושפעים. סף שולי רווח 10% מפיל עסקים עם שוליים נמוכים מטבעם (COST, WMT, ביטוח בריאות) — לכן הם WATCH ולא NON-CORE אוטומטית.
A36: מקור הנתונים: Bigdata.com (https://bigdata.com), ספק FMP, דוחות שנתיים, נשלף 13.10.2026. סיכון ותקרות: risk_engine.csv מה־DB שלנו (5 שנים).

Sheet Data
A1: סימול | B1: שם | C1: סקטור | D1: תעשייה | E1: מטבע | F1: מחלקה | G1: סוף שנת הדוח האחרונה | H1: שנים בנתונים | I1: הכנסות שנה אחרונה (מיליון) | J1: צמיחת הכנסות שנתית 3 שנים | K1: שינוי הכנסות שנה אחרונה | L1: שולי רווח תפעולי | M1: שנים עם רווח נקי חיובי | N1: FCF שנה אחרונה (מיליון) | O1: שולי FCF | P1: שנים עם FCF חיובי | Q1: שנים עם תזרים מפעילות חיובי | R1: ROIC | S1: ROE שנה אחרונה | T1: חוב נטו (מיליון) | U1: חוב נטו / EBITDA | V1: כיסוי ריבית | W1: שינוי במספר המניות 3 שנים | X1: תגמול במניות / הכנסות | Y1: P/E נוכחי (TTM) | Z1: חציון P/E שנתי של החברה | AA1: P/E נוכחי / חציון עצמי | AB1: EV/EBITDA נוכחי | AC1: FCF yield נוכחי | AD1: צמיחת הכנסות צפויה (אנליסטים, מידע בלבד) | AE1: הערות על הנתונים
A2: ABNB | B2: Airbnb Inc. | C2: Consumer Services | D2: Travel and Tourism | E2: USD | F2: STD | G2: 2025-12-31 | H2: 5 | I2: 12305 | J2: 0.13575506 | K2: 0.10835885 | L2: 0.21202763 | M2: 4 | N2: 4646 | O2: 0.37757009 | P2: 5 | Q2: 5 | R2: 0.20689878 | S2: 0.30625686 | T2: -8743 | U2: -3.2381481 | V2: 999 | W2: -0.083823529 | X2: 0.1293783 | Y2: 37.129955 | Z2: 30.075324 | AA2: =IF(AND(ISNUMBER(Y2),ISNUMBER(Z2),Y2>0,Z2>0),Y2/Z2,"") -> 1.2345654 | AB2: 30.89251 | AC2: 0.049967079 | AD2: 0.15243471 | AE2: Cash includes customer funds per source (cash_and_short_term_investments 11014000000). FY2023 net_income includes tax benefit (income_tax -2690000000). FY2025 net_income field is 2511000000 (bottom_line_net_income 2514000000). FY2026+ are estimates. capex 0 and interest_expense 0 as returned for FY2024/FY2025.
A3: ADBE | B3: Adobe Inc. | C3: Technology | D3: Software | E3: USD | F3: STD | G3: 2025-11-28 | H3: 5 | I3: 23769 | J3: 0.1052234 | K3: 0.10527784 | L3: 0.3662754 | M3: 5 | N3: 9852 | O3: 0.41448946 | P3: 5 | Q3: 5 | R3: 0.58904933 | S3: 0.61343887 | T3: 53 | U3: 0.0053998981 | V3: 33.102662 | W3: -0.093418259 | X3: 0.081703059 | Y3: 13.222067 | Z3: 41.473473 | AA3: =IF(AND(ISNUMBER(Y3),ISNUMBER(Z3),Y3>0,Z3>0),Y3/Z3,"") -> 0.31880781 | AB3: 9.4495116 | AC3: 0.11595158 | AD3: 0.11955212 | AE3: Fiscal year ends November (report dates late Nov/early Dec). No dividends.
A4: ADP | B4: Automatic Data Processing Inc. | C4: Industrials | D4: Financial Administration | E4: USD | F4: STD | G4: 2026-06-30 | H4: 5 | I4: 21947.5 | J4: 0.068085696 | K4: 0.067438682 | L4: 0.18582526 | M4: 5 | N4: 5244.6 | O4: 0.23896116 | P4: 5 | Q4: 5 | R4: 0.45559694 | S4: 0.73177809 | T4: 1040.7 | U4: 0.16138887 | V4: 8.8815331 | W4: -0.039141208 | X4: 0.011053651 | Y4: 25.116682 | Z4: 26.641212 | AA4: =IF(AND(ISNUMBER(Y4),ISNUMBER(Z4),Y4>0,Z4>0),Y4/Z4,"") -> 0.94277549 | AB4: 17.241395 | AC4: 0.045209355 | AD4: 0.057673829 | AE4: Fiscal year ends June 30. FY2026 operating_income (4078400000) is below ebit (5862500000) as returned. FY2026 balance sheet: other_non_current_assets 48622400000 and total_current_assets 8603300000; TTM current_ratio 0.172 vs FY2025 1.048 as returned. Total assets include large other_current_assets in earlier years. TTM and FY2026 key_metrics differ (TTM pe 25.1 vs FY 20.4) as returned. Provider FMP.
A5: ANET | B5: Arista Networks Inc. | C5: Technology | D5: Internet Services | E5: USD | F5: STD | G5: 2025-12-31 | H5: 5 | I5: 9005.7 | J5: 0.27146526 | K5: 0.28595908 | L5: 0.42818437 | M5: 5 | N5: 4252.4 | O5: 0.47218984 | P5: 5 | Q5: 5 | R5: 1.8717782 | S5: 0.28385271 | T5: -10743 | U5: -2.4854823 | V5: 999 | W5: 0.0077932748 | X5: 0.048769113 | Y5: 65.694704 | Z5: 46.964158 | AA5: =IF(AND(ISNUMBER(Y5),ISNUMBER(Z5),Y5>0,Z5>0),Y5/Z5,"") -> 1.3988264 | AB5: 51.790012 | AC5: 0.019414865 | AD5: 0.40848228 | AE5: No debt (total_debt 0, interest_expense 0, interest_coverage 0). Share/EPS data split-adjusted as returned. TTM key metrics (pe 65.7, ev_to_ebitda 51.8) differ from FY2025 (47.0, 37.7).
A6: APH | B6: Amphenol Corp. | C6: Industrials | D6: Electrical Components and Equipment | E6: USD | F6: STD | G6: 2025-12-31 | H6: 5 | I6: 23094.7 | J6: 0.22306606 | K6: 0.51712246 | L6: 0.25411025 | M6: 5 | N6: 4378.1 | O6: 0.18957163 | P6: 5 | Q6: 5 | R6: 0.2637573 | S6: 0.3160914 | T6: 4067.8 | U6: 0.58354852 | V6: 15.955954 | W6: 0.028582931 | X6: 0 | Y6: 40.442857 | Z6: 32.887218 | AA6: =IF(AND(ISNUMBER(Y6),ISNUMBER(Z6),Y6>0,Z6>0),Y6/Z6,"") -> 1.2297439 | AB6: 24.566977 | AC6: 0.022177829 | AD6: 0.54057372 | AE6: stock_based_compensation FY2025 returned 0. total_equity includes minority_interest (FY2025 stockholders equity 13413100000). FY2026+ are estimates.
A7: APP | B7: AppLovin Corp. | C7: Consumer Services | D7: Media Agencies | E7: USD | F7: STD | G7: 2025-12-31 | H7: 5 | I7: 5480.717 | J7: 0.24838113 | K7: 0.69994367 | L7: 0.75754942 | M7: 4 | N7: 3942.776 | O7: 0.71939055 | P7: 5 | Q7: 5 | R7: 1.027471 | S7: 1.5617226 | T7: 1057.645 | U7: 0.24287414 | V7: 20.056005 | W7: -0.079657048 | X7: 0.038392969 | Y7: 20.72456 | Z7: 68.836043 | AA7: =IF(AND(ISNUMBER(Y7),ISNUMBER(Z7),Y7>0,Z7>0),Y7/Z7,"") -> 0.30107134 | AB7: 16.477873 | AC7: 0.049444747 | AD7: 0.48208055 | AE7: FY2021 eps_diluted returned as 0.093. FY2021 total_equity uses total_equity 2138291000 (stockholders equity 2138090000). TTM market data (pe 20.7, EV 91.5B) appears inconsistent with FY2025 year-end valuation (pe 68.5, EV 229B); copied as returned.
A8: ASML | B8: ASML Holding N.V. | E8: EUR | F8: STD | G8: 2025-12-31 | H8: 5 | I8: 32667.3 | J8: 0.15551134 | K8: 0.1558368 | L8: 0.34595452 | M8: 5 | N8: 11084.9 | O8: 0.33932709 | P8: 5 | Q8: 5 | R8: 0.83587106 | S8: 0.48997053 | T8: -8931 | U8: -0.71838803 | V8: 999 | W8: -0.022864322 | X8: 0 | Y8: 55.428156 | Z8: 36.087904 | AA8: =IF(AND(ISNUMBER(Y8),ISNUMBER(Z8),Y8>0,Z8>0),Y8/Z8,"") -> 1.5359206 | AB8: 42.310624 | AC8: 0.016987946 | AD8: 0.34852415 | AE8: FOREIGN: all figures in EUR. Sector and industry not returned by tearsheet (null). FY ends Dec. FY2025 interest_expense 0 and stock_based_compensation 0 as returned; TTM interest_coverage 0 as returned. Cash-flow net income FY2022 6395800000 differs from income-statement net_income 5624200000.
A9: AXP | B9: American Express Co. | C9: Financials | D9: Consumer Finance | E9: USD | F9: FIN | G9: 2025-12-31 | H9: 5 | I9: 80464 | J9: 0.1309512 | K9: 0.084405871 | L9: 0.17144313 | M9: 5 | N9: 16003 | O9: 0.19888397 | P9: 5 | Q9: 5 | R9: 0.25522963 | S9: 0.32362431 | T9: 9225 | U9: 0.59240945 | V9: 1.6753704 | W9: -0.074468085 | X9: 0.0068477829 | Y9: 18.892056 | Z9: 16.682102 | AA9: =IF(AND(ISNUMBER(Y9),ISNUMBER(Z9),Y9>0,Z9>0),Y9/Z9,"") -> 1.1324746 | AB9: 8.9926782 | AC9: 0.072181816 | AD9: -0.012327052 | AE9: Financial/consumer-finance format (negative working capital, interest expense large). TTM current_ratio 1.55 vs FY ~0.28. FY2021 gross_profit exceeds revenue (cost_of_revenue negative). SALES 2030 estimate (76.4B) lower than 2029 - copied as returned but not included (only first two years).
A10: BAC | B10: Bank of America Corp. | C10: Financials | D10: Diversified Banks | E10: USD | F10: FIN | G10: 2025-12-31 | H10: 5 | I10: 191567 | J10: 0.1852435 | K10: -0.0045054408 | L10: 0.19677189 | M10: 5 | N10: 12613 | O10: 0.065841194 | P10: 2 | Q10: 2 | R10: 0.0096185834 | S10: 0.10060908 | T10: -597828 | U10: -14.942338 | V10: 0.48037467 | W10: -0.075984083 | X10: 0.020885643 | Y10: 12.329932 | Z10: 12.358333 | AA10: =IF(AND(ISNUMBER(Y10),ISNUMBER(Z10),Y10>0,Z10>0),Y10/Z10,"") -> 0.99770185 | AB10: 23.550256 | AC10: 0.24552378 | AD10: -0.3557528 | AE10: Bank format: capex 0, operating cash flow and FCF volatile/not meaningful (FCF-based multiples meaningless), TTM current_ratio 0.07, interest_coverage <1, TTM ROIC equals ROA. FY2021 gross_profit exceeds revenue (small cost_of_revenue). Estimated SALES (123B for 2026) on a different basis than reported FY2025 revenue (191.6B).
A11: BKNG | B11: Booking Holdings Inc. | C11: Consumer Services | D11: Travel and Tourism | E11: USD | F11: STD | G11: 2025-12-31 | H11: 5 | I11: 26917 | J11: 0.16348699 | K11: 0.13387253 | L11: 0.34483783 | M11: 5 | N11: 9087 | O11: 0.33759334 | P11: 5 | Q11: 5 | R11: 0.71229483 | T11: 1508 | U11: 0.16361072 | V11: 5.7402597 | W11: -0.18508439 | X11: 0.022922317 | Y11: 17.478267 | Z11: 29.891717 | AA11: =IF(AND(ISNUMBER(Y11),ISNUMBER(Z11),Y11>0,Z11>0),Y11/Z11,"") -> 0.5847194 | AB11: 11.666704 | AC11: 0.07795292 | AD11: 0.086761577 | AE11: NEGATIVE EQUITY: total_equity -5578000000 (FY2025), -4020000000 (FY2024), -2744000000 (FY2023); price_to_book, return_on_equity and debt_to_equity are negative in source. cost_of_revenue 0 so gross_profit equals revenue. ttm pe_ratio 17.48 vs FY2025 fy_pe_ratio 32.16 copied as returned (not reconciled). FY2026+ are estimates.
A12: BSX | B12: Boston Scientific Corp. | C12: Health Care | D12: Medical Equipment | E12: USD | F12: STD | G12: 2025-12-31 | H12: 5 | I12: 20074 | J12: 0.1654189 | K12: 0.19866245 | L12: 0.19781807 | M12: 5 | N12: 3658 | O12: 0.18222576 | P12: 5 | Q12: 5 | R12: 0.10570818 | S12: 0.1179307 | T12: 10373 | U12: 2.0331243 | V12: 11.378223 | W12: 0.038063485 | X12: 0.014894889 | Y12: 17.340726 | Z12: 61.34296 | AA12: =IF(AND(ISNUMBER(Y12),ISNUMBER(Z12),Y12>0,Z12>0),Y12/Z12,"") -> 0.28268485 | AB12: 13.097693 | AC12: 0.056710704 | AD12: 0.056587788 | AE12: total_equity includes minority_interest (FY2025 stockholders equity 24233000000). FY2022 common_stock_repurchased is +136000000 as returned. Source ttm pe_ratio 17.34 and FY2025 fy_pe_ratio 48.65 copied as returned (they differ widely; not reconciled). FY2026+ are estimates.
A13: CAT | B13: Caterpillar Inc. | C13: Industrials | D13: Commercial Vehicles and Trucks | E13: USD | F13: STD | G13: 2025-12-31 | H13: 5 | I13: 67589 | J13: 0.043832316 | K13: 0.042895277 | L13: 0.16585539 | M13: 5 | N13: 7453 | O13: 0.11026942 | P13: 5 | Q13: 5 | R13: 0.16199422 | S13: 0.41622103 | T13: 33350 | U13: 2.2450353 | V13: 10.883495 | W13: -0.11576169 | X13: 0.0035804643 | Y13: 33.229649 | Z13: 17.329422 | AA13: =IF(AND(ISNUMBER(Y13),ISNUMBER(Z13),Y13>0,Z13>0),Y13/Z13,"") -> 1.9175279 | AB13: 22.987763 | AC13: 0.024872785 | AD13: 0.17763129 | AE13: Consolidated incl. Financial Products (total_debt includes financial-services debt, net_debt_to_ebitda/debt_to_equity reflect that). total_equity includes minority_interest (tiny). FY2026+ are estimates.
A14: CB | B14: Chubb Ltd. | C14: Financials | D14: Property and Casualty Insurance | E14: USD | F14: FIN | G14: 2025-12-31 | H14: 5 | I14: 59783 | J14: 0.11631632 | K14: 0.064701692 | L14: 0.21818912 | M14: 5 | N14: 14537 | O14: 0.24316277 | P14: 5 | Q14: 5 | R14: 0.18789563 | S14: 0.129232 | T14: -24936 | U14: -1.7673825 | V14: 17.073298 | W14: -0.063814113 | X14: 0 | Y14: 12.17428 | Z14: 12.044464 | AA14: =IF(AND(ISNUMBER(Y14),ISNUMBER(Z14),Y14>0,Z14>0),Y14/Z14,"") -> 1.0107781 | AB14: 12.224919 | AC14: 0.12027202 | AD14: -0.013200377 | AE14: Insurance format: capex 0 and free_cash_flow equals operating_cash_flow as returned; cash_and_short_term_investments includes short-term investments; FY2021 cash_and_short_term_investments 97913000000 as returned. FY2024 shares_diluted 411905820 as returned (income stmt).
A15: CME | B15: CME Group Inc. | C15: Financials | D15: Investment Services | E15: USD | F15: STD | G15: 2025-12-31 | H15: 5 | I15: 6520.6 | J15: 0.091135245 | K15: 0.06370206 | L15: 0.64863663 | M15: 5 | N15: 4193.6 | O15: 0.643131 | P15: 5 | Q15: 5 | R15: 0.12102406 | S15: 0.14078153 | T15: -1119.6 | U15: -0.19382985 | V15: 32.609869 | W15: 0.0029288854 | X15: 0.014538539 | Y15: 23.395781 | Z15: 23.965944 | AA15: =IF(AND(ISNUMBER(Y15),ISNUMBER(Z15),Y15>0,Z15>0),Y15/Z15,"") -> 0.97620942 | AB15: 18.33113 | AC15: 0.042059365 | AD15: 0.081167463 | AE15: Exchange operator; balance sheet includes large clearing-house/performance-bond items (other_current_assets ~160B, total_assets ~198B). Provider cash_end_of_period includes restricted/clearing cash (164B) so net_change_in_cash is large. Provider FMP.
A16: CRM | B16: Salesforce, Inc. | E16: USD | F16: STD | G16: 2026-01-31 | H16: 5 | I16: 41525 | J16: 0.098200061 | K16: 0.095791001 | L16: 0.21473811 | M16: 5 | N16: 14402 | O16: 0.34682721 | P16: 5 | Q16: 5 | R16: 0.10552979 | S16: 0.12608637 | T16: 7611 | U16: 0.57873926 | V16: 27.521605 | W16: -0.04112337 | X16: 0.084503311 | Y16: 21.703955 | Z16: 66.138824 | AA16: =IF(AND(ISNUMBER(Y16),ISNUMBER(Z16),Y16>0,Z16>0),Y16/Z16,"") -> 0.32815755 | AB16: 13.655629 | AC16: 0.077501806 | AD16: 0.11468764 | AE16: Fiscal year ends January; source fiscal_year N has report_date N-01-31 (fiscal_year 2026 = FYE 2026-01-31). Estimates are for fiscal_year 2027 (FYE 2027-01-31) and 2028 as returned, since fiscal_year 2026 is already reported. sector and industry not returned by the requested sections. Ttm and FY values copied as returned (fy_pe_ratio FY2023 799.857). FY2027+ are estimates.
A17: CSCO | B17: Cisco Systems Inc. | C17: Technology | D17: Computer Services | E17: USD | F17: STD | G17: 2026-07-25 | H17: 5 | I17: 63325 | J17: 0.035710853 | K17: 0.11774985 | L17: 0.24268456 | M17: 5 | N17: 12767 | O17: 0.20161074 | P17: 5 | Q17: 5 | R17: 0.18999562 | S17: 0.26383613 | T17: 13615 | U17: 0.6801039 | V17: 10.454422 | W17: -0.028745432 | X17: 0.060481642 | Y17: 34.025298 | Z17: 18.776471 | AA17: =IF(AND(ISNUMBER(Y17),ISNUMBER(Z17),Y17>0,Z17>0),Y17/Z17,"") -> 1.8121242 | AB17: 23.634159 | AC17: 0.030170581 | AD17: 0.15181287 | AE17: Fiscal year ends July; FY2026 (2026-07-25) already reported. Tearsheet source FMP.
A18: ETN | B18: Eaton Corp. PLC | C18: Industrials | D18: Diversified Industrials | E18: USD | F18: STD | G18: 2025-12-31 | H18: 5 | I18: 27448 | J18: 0.097699792 | K18: 0.10330412 | L18: 0.19050568 | M18: 5 | N18: 3553 | O18: 0.12944477 | P18: 5 | Q18: 5 | R18: 0.13845852 | S18: 0.2100262 | T18: 10366 | U18: 1.6713963 | V18: 19.806818 | W18: -0.028193613 | X18: 0.0018216263 | Y18: 43.274848 | Z18: 30.363203 | AA18: =IF(AND(ISNUMBER(Y18),ISNUMBER(Z18),Y18>0,Z18>0),Y18/Z18,"") -> 1.4252399 | AB18: 28.887522 | AC18: 0.027184323 | AD18: 0.20101368 | AE18: Irish-domiciled, reports in USD. find_securities with query ETN returned only private entities; resolved via query 'Eaton Corporation' (id C4073B, listing XNYS:ETN). stock_based_compensation FY2025 is -50000000 and 0 for FY2021-2024 as returned. total_equity includes minority_interest (FY2025 stockholders equity 19425000000). FY2026+ are estimates.
A19: GE | B19: GE Aerospace | C19: Industrials | D19: Diversified Industrials | E19: USD | F19: STD | G19: 2025-12-31 | H19: 5 | I19: 45855 | J19: 0.16315436 | K19: 0.18482249 | L19: 0.19125504 | M19: 4 | N19: 7264 | O19: 0.15841239 | P19: 5 | Q19: 5 | R19: 0.2566037 | S19: 0.46057784 | T19: 8102 | U19: 0.67164055 | V19: 10.403321 | W19: -0.026459854 | X19: 0 | Y19: 35.960094 | Z19: 32.681506 | AA19: =IF(AND(ISNUMBER(Y19),ISNUMBER(Z19),Y19>0,Z19>0),Y19/Z19,"") -> 1.1003193 | AB19: 26.28023 | AC19: 0.0263019 | AD19: 0.097224392 | AE19: Entity is GE Aerospace (post-spin history restated/mixed: FY2021-2023 include prior conglomerate basis, FY2021 net loss, FY2022 eps 0.043 and fy_pe_ratio 1212.79 as returned). FY2026 EPS estimate 7.92883 is below FY2025 EPS 8.16 as returned. Tearsheet source FMP.
A20: GOOGL | B20: Alphabet Inc. | C20: Technology | D20: Internet Services | E20: USD | F20: STD | G20: 2025-12-31 | H20: 5 | I20: 402836 | J20: 0.12511746 | K20: 0.15090081 | L20: 0.32063917 | M20: 5 | N20: 73266 | O20: 0.1818755 | P20: 5 | Q20: 5 | R20: 0.29346142 | S20: 0.31827869 | T20: -67552 | U20: -0.37383922 | V20: 175.49592 | W20: -0.07059807 | X20: 0.061943322 | Y20: 17.542949 | Z20: 24.131849 | AA20: =IF(AND(ISNUMBER(Y20),ISNUMBER(Z20),Y20>0,Z20>0),Y20/Z20,"") -> 0.72696249 | AB20: 13.257955 | AC20: 0.012479964 | AD20: 0.23705027 | AE20: Estimate EPS FY2027 (15.21734) is lower than FY2026 (20.59129) as returned. TTM net_margin 0.5477 and ttm pe 17.54 as returned (TTM includes large other income). Tearsheet source FMP.
A21: GS | B21: Goldman Sachs Group Inc. | C21: Financials | D21: Investment Services | E21: USD | F21: FIN | G21: 2025-12-31 | H21: 5 | I21: 125097 | J21: 0.22106901 | K21: -0.013842794 | L21: 0.17468045 | M21: 5 | N21: -47218 | O21: -0.3774511 | P21: 2 | Q21: 2 | R21: 108.84351 | S21: 0.13743879 | T21: -14993 | U21: -0.62382458 | V21: 0.3270572 | W21: -0.1130969 | X21: 0.02753863 | Y21: 16.797257 | Z21: 13.8918 | AA21: =IF(AND(ISNUMBER(Y21),ISNUMBER(Z21),Y21>0,Z21>0),Y21/Z21,"") -> 1.209149 | AB21: 10.350864 | AC21: -0.15741985 | AD21: -0.43368617 | AE21: Bank/broker format: OCF/FCF negative and not meaningful; debt/net debt ratios not meaningful. TTM block appears anomalous as returned (return_on_invested_capital 108.84, price_to_book 125.17, debt_to_equity 0.042, current_ratio 1.92, enterprise_value 263636507650, ttm book_value_per_share 0.409) and is inconsistent with FY2025 values. FY2025 revenue 125097000000 vs FY2026 SALES estimate 70844160598 (basis mismatch as returned). Tearsheet source FMP.
A22: INTU | B22: Intuit Inc. | C22: Technology | D22: Software | E22: USD | F22: STD | G22: 2026-07-31 | H22: 5 | I22: 21448 | J22: 0.14286999 | K22: 0.13897297 | L22: 0.28799888 | M22: 5 | N22: 8617 | O22: 0.4017624 | P22: 5 | Q22: 5 | R22: 0.24142037 | S22: 0.24041702 | T22: 1221 | U22: 0.17151285 | V22: 24.128906 | W22: -0.021201413 | X22: 0.095859754 | Y22: 18.511192 | Z22: 60.341981 | AA22: =IF(AND(ISNUMBER(Y22),ISNUMBER(Z22),Y22>0,Z22>0),Y22/Z22,"") -> 0.30677136 | AB22: 12.08232 | AC22: 0.10295152 | AD22: 0.091753967 | AE22: Fiscal year ends July; FY2026 (ended 2026-07-31) is the latest. TTM ratios equal FY2026 largely. FY2026 balance sheet shows additional_paid_in_capital 0 and treasury_stock 0 (format change). FY2026 market cap 87.2B vs FY2025 219.8B (large drop).
A23: ISRG | B23: Intuitive Surgical Inc. | C23: Health Care | D23: Medical Equipment | E23: USD | F23: STD | G23: 2025-12-31 | H23: 5 | I23: 10064.7 | J23: 0.17386717 | K23: 0.20505023 | L23: 0.29265651 | M23: 5 | N23: 2490.7 | O23: 0.24746888 | P23: 5 | Q23: 5 | R23: 0.18903498 | S23: 0.15918224 | T23: -5632.1 | U23: -1.4120847 | V23: 999 | W23: 0.0019337017 | X23: 0.078313313 | Y23: 47.754237 | Z23: 71.330645 | AA23: =IF(AND(ISNUMBER(Y23),ISNUMBER(Z23),Y23>0,Z23>0),Y23/Z23,"") -> 0.66947715 | AB23: 32.296135 | AC23: 0.021584134 | AD23: 0.1684715 | AE23: interest_expense returned as 0 (no meaningful debt); interest_coverage 0 in source. total_equity includes minority_interest (FY2025 stockholders equity 17824000000). FY2026+ are estimates.
A24: JNJ | B24: Johnson & Johnson Co. | C24: Health Care | D24: Pharmaceuticals | E24: USD | F24: STD | G24: 2025-12-28 | H24: 5 | I24: 94193 | J24: 0.05599285 | K24: 0.060481193 | L24: 0.27173994 | M24: 5 | N24: 19698 | O24: 0.20912382 | P24: 5 | Q24: 5 | R24: 0.18487625 | S24: 0.32870597 | T24: 27831 | U24: 0.67789551 | V24: 26.360453 | W24: -0.08802883 | X24: 0.014374741 | Y24: 28.760694 | Z24: 21.631778 | AA24: =IF(AND(ISNUMBER(Y24),ISNUMBER(Z24),Y24>0,Z24>0),Y24/Z24,"") -> 1.3295575 | AB24: 18.80106 | AC24: 0.030892527 | AD24: 0.075721073 | AE24: FY2023 net_income (35.153B) differs from net_income_from_continuing_operations (13.326B). FY2025 total_other_income_expenses_net = 6.985B; FY2024 = -5.462B. FY2022-2021 fiscal weeks end on Jan 1 / Jan 2 dates. FY2025 shares_diluted equals FY2024 value as returned (2429400000).
A25: JPM | B25: JPMorgan Chase & Co. | C25: Financials | D25: Diversified Banks | E25: USD | F25: FIN | G25: 2025-12-31 | H25: 5 | I25: 279745 | J25: 0.22061699 | K25: 0.033073722 | L25: 0.25950419 | M25: 5 | N25: -147782 | O25: -0.52827396 | P25: 3 | Q25: 3 | R25: 0.078828428 | S25: 0.15740071 | T25: -537369 | U25: -6.6002874 | V25: 0.74153711 | W25: -0.059360269 | X25: 0 | Y25: 14.092585 | Z25: 11.082645 | AA25: =IF(AND(ISNUMBER(Y25),ISNUMBER(Z25),Y25>0,Z25>0),Y25/Z25,"") -> 1.2715904 | AB25: 15.215874 | AC25: -0.18182341 | AD25: -0.2555095 | AE25: Bank format: capex 0, operating cash flow and FCF negative/not meaningful (FCF-based multiples and yields meaningless), current_ratio TTM 10.28 vs FY 0.52, interest_expense exceeds operating income (interest_coverage <1), SBC 0. FY2021 gross_profit exceeds revenue (negative cost_of_revenue). Estimated SALES (208B for 2026) is on a different revenue basis than reported FY2025 revenue (279.7B).
A26: KLAC | B26: KLA Corp. | C26: Technology | D26: Semiconductors | E26: USD | F26: STD | G26: 2026-06-30 | H26: 5 | I26: 13579.476 | J26: 0.08964649 | K26: 0.1170858 | L26: 0.41686292 | M26: 5 | N26: 3767.134 | O26: 0.2774138 | P26: 5 | Q26: 5 | R26: 0.58849094 | S26: 0.7607729 | T26: 1249.305 | U26: 0.20633442 | V26: 19.901491 | W26: -0.058984562 | X26: 0.022841161 | Y26: 50.02443 | Z26: 29.338356 | AA26: =IF(AND(ISNUMBER(Y26),ISNUMBER(Z26),Y26>0,Z26>0),Y26/Z26,"") -> 1.7050864 | AB26: 40.960436 | AC26: 0.015470544 | AD26: 0.33821263 | AE26: Fiscal year ends June. Name returned 'KLA Corp.' (ticker KLAC on XNAS). Split-style fractional EPS values returned (e.g. 3.037, 2.028). Large gap between FY2026 key metrics (pe 82.0, ev_to_ebitda 66.1) and TTM (pe 50.0, ev_to_ebitda 41.0); TTM and FY2026 financial statement ratios are nearly identical, so the difference is price-date basis. Total equity thin relative to buybacks (ROE 0.85).
A27: KO | B27: Coca-Cola Co. | C27: Consumer Goods | D27: Soft Drinks | E27: USD | F27: STD | G27: 2025-12-31 | H27: 5 | I27: 47941 | J27: 0.036890141 | K27: 0.018699135 | L27: 0.28706118 | M27: 5 | N27: 5296 | O27: 0.11046912 | P27: 5 | Q27: 5 | R27: 0.16078767 | S27: 0.382407 | T27: 33342 | U27: 1.782804 | V27: 8.3204353 | W27: -0.0085057471 | X27: 0.0058196533 | Y27: 26.963964 | Z27: 25.206478 | AA27: =IF(AND(ISNUMBER(Y27),ISNUMBER(Z27),Y27>0,Z27>0),Y27/Z27,"") -> 1.0697236 | AB27: 21.025761 | AC27: 0.037007618 | AD27: 0.038806306
A28: LLY | B28: Eli Lilly & Co. | C28: Health Care | D28: Pharmaceuticals | E28: USD | F28: STD | G28: 2025-12-31 | H28: 5 | I28: 65179 | J28: 0.31687375 | K28: 0.4470395 | L28: 0.45560687 | M28: 5 | N28: 8972 | O28: 0.1376517 | P28: 4 | Q28: 5 | R28: 0.37979343 | S28: 0.77784059 | T28: 35235 | U28: 1.1117597 | V28: 37.339369 | W28: -0.054915795 | X28: 0.0096043204 | Y28: 39.28103 | Z28: 55.683409 | AA28: =IF(AND(ISNUMBER(Y28),ISNUMBER(Z28),Y28>0,Z28>0),Y28/Z28,"") -> 0.70543508 | AB28: 26.637113 | AC28: 0.018107411 | AD28: 0.36094005 | AE28: FY2026 and later are estimates; 5 fiscal years returned. Tearsheet also returned FY2028-2030 estimates (not copied).
A29: LMT | B29: Lockheed Martin Corp. | C29: Industrials | D29: Defense | E29: USD | F29: STD | G29: 2025-12-31 | H29: 5 | I29: 75057 | J29: 0.043880667 | K29: 0.056500992 | L29: 0.10300172 | M29: 5 | N29: 6908 | O29: 0.092036719 | P29: 5 | Q29: 5 | R29: 0.25133704 | S29: 0.7464663 | T29: 17579 | U29: 2.0143234 | V29: 6.9150268 | W29: -0.12358277 | X29: 0.0040502551 | Y29: 18.559622 | Z29: 21.703439 | AA29: =IF(AND(ISNUMBER(Y29),ISNUMBER(Z29),Y29>0,Z29>0),Y29/Z29,"") -> 0.8551466 | AB29: 13.009076 | AC29: 0.074815245 | AD29: 0.078599455 | AE29: Calendar fiscal year. Provider classifies industry as Defense. Operating_income (FY2025 7731000000) exceeds gross_profit (7619000000) as returned. Provider FMP.
A30: LRCX | B30: Lam Research Corp. | C30: Technology | D30: Semiconductors | E30: USD | F30: STD | G30: 2026-06-28 | H30: 5 | I30: 23232.69 | J30: 0.10059634 | K30: 0.26020858 | L30: 0.35294213 | M30: 5 | N30: 4891.252 | O30: 0.21053318 | P30: 5 | Q30: 5 | R30: 0.5881824 | S30: 0.58258696 | T30: -1457.606 | U30: -0.16746381 | V30: 999 | W30: -0.071585906 | X30: 0.01663092 | Y30: 53.464594 | Z30: 23.342926 | AA30: =IF(AND(ISNUMBER(Y30),ISNUMBER(Z30),Y30>0,Z30>0),Y30/Z30,"") -> 2.2903982 | AB30: 44.309349 | AC30: 0.012634766 | AD30: 0.50410787 | AE30: FY ends late June. FY2026 interest_expense returned 0 (FY2025 178203000). TTM block (pe 53.5, EV 385.7B) differs from FY2026 year-end valuation (pe 71.0, EV 514.3B); copied as returned. FY2026 EBITDA/EV figures as returned.
A31: MA | B31: Mastercard Inc. | C31: Financials | D31: Consumer Finance | E31: USD | F31: STD | G31: 2025-12-31 | H31: 5 | I31: 32791 | J31: 0.13821985 | K31: 0.16416374 | L31: 0.57628618 | M31: 5 | N31: 16433 | O31: 0.50114361 | P31: 5 | Q31: 5 | R31: 0.94198826 | S31: 1.9323522 | T31: 8102 | U31: 0.39437305 | V31: 26.17313 | W31: -0.075180227 | X31: 0.018206215 | Y31: 33.017298 | Z31: 35.962057 | AA31: =IF(AND(ISNUMBER(Y31),ISNUMBER(Z31),Y31>0,Z31>0),Y31/Z31,"") -> 0.91811483 | AB31: 24.328065 | AC31: 0.030932939 | AD31: 0.1364896 | AE31: Very small equity (buybacks) so ROE/price_to_book extreme as returned; cost_of_revenue 0 so gross_profit equals revenue as returned; TTM ROE 2.324587116608279 and debt_to_equity 4.39190875066833 as returned.
A32: META | B32: Meta Platforms Inc. | C32: Technology | D32: Internet Services | E32: USD | F32: STD | G32: 2025-12-31 | H32: 5 | I32: 200966 | J32: 0.19893831 | K32: 0.22167038 | L32: 0.41437855 | M32: 5 | N32: 46109 | O32: 0.22943682 | P32: 5 | Q32: 5 | R32: 0.29965219 | S32: 0.27829665 | T32: 2305 | U32: 0.022047289 | V32: 71.481545 | W32: -0.047372317 | X32: 0.10164406 | Y32: 28.563731 | Z32: 23.791548 | AA32: =IF(AND(ISNUMBER(Y32),ISNUMBER(Z32),Y32>0,Z32>0),Y32/Z32,"") -> 1.2005831 | AB32: 18.097181 | AC32: 0.020950257 | AD32: 0.26450596 | AE32: FY2025 income_tax 25474000000 (high vs prior year). Dividends began FY2024.
A33: MRK | B33: Merck & Co. Inc. | C33: Health Care | D33: Pharmaceuticals | E33: USD | F33: STD | G33: 2025-12-31 | H33: 5 | I33: 64926 | J33: 0.030772503 | K33: 0.011812742 | L33: 0.3617349 | M33: 5 | N33: 12360 | O33: 0.19037058 | P33: 5 | Q33: 5 | R33: 0.20933917 | S33: 0.34662565 | T33: 35969 | U33: 1.2726983 | V33: 17.307296 | W33: -0.013768686 | X33: 0 | Y33: 113.94048 | Z33: 14.852713 | AA33: =IF(AND(ISNUMBER(Y33),ISNUMBER(Z33),Y33>0,Z33>0),Y33/Z33,"") -> 7.6713577 | AB33: 28.919703 | AC33: 0.045161536 | AD33: 0.032915932 | AE33: FY2023 net income 365000000 and eps 0.14 (distorted by acquired IPR&D charge) so fy_pe_ratio 778.7 as returned. TTM net_margin 0.0478 and pe 113.9 are TTM figures as returned and differ sharply from FY2025 (TTM likely includes a large one-time charge). FY2026 EPS estimate 2.66326 as returned. FY2025 SBC returned as 0. Tearsheet source FMP.
A34: MRSH | B34: Marsh & McLennan Cos. Inc. | C34: Financials | D34: Insurance Brokers | E34: USD | F34: STD | G34: 2025-12-31 | H34: 5 | I34: 26981 | J34: 0.092000315 | K34: 0.10315643 | L34: 0.23064379 | M34: 5 | N34: 5001 | O34: 0.18535266 | P34: 5 | Q34: 5 | R34: 0.14426651 | S34: 0.27162912 | T34: 18762 | U34: 2.5371197 | V34: 6.4822917 | W34: -0.02970297 | X34: 0.014602869 | Y34: 21.519488 | Z34: 25.746667 | AA34: =IF(AND(ISNUMBER(Y34),ISNUMBER(Z34),Y34>0,Z34>0),Y34/Z34,"") -> 0.83581648 | AB34: 17.583872 | AC34: 0.056540463 | AD34: 0.058911118 | AE34: Ticker MRSH resolved to Marsh & McLennan Cos. Inc. (listing XNYS:MRSH, id 9B5968). Tangible book value negative (tangible_book_value_per_share FY2025 -29.23). EPS estimate (2026 10.45) is above FY2025 diluted EPS 8.43 as returned. total_equity includes minority interest (FY2025 total_stockholders_equity 15100000000).
A35: MS | B35: Morgan Stanley Co. | C35: Financials | D35: Investment Services | E35: USD | F35: FIN | G35: 2025-12-31 | H35: 5 | I35: 114983 | J35: 0.22546856 | K35: 0.11477047 | L35: 0.19093257 | M35: 5 | N35: 46100 | O35: 0.40092883 | P35: 2 | Q35: 3 | R35: 0.35952115 | S35: 0.14967333 | T35: -64411 | U35: -2.4203743 | V35: 0.44788543 | W35: -0.070052539 | X35: 0.016750302 | Y35: 15.146302 | Z35: 15.636816 | AA35: =IF(AND(ISNUMBER(Y35),ISNUMBER(Z35),Y35>0,Z35>0),Y35/Z35,"") -> 0.96863085 | AB35: 21.658093 | AC35: -0.052774125 | AD35: -0.28913086 | AE35: Bank/broker format: OCF/FCF swing wildly (negative FY2022-2024) and are not meaningful; debt/net debt ratios not meaningful. FY2025 revenue 114983000000 vs FY2026 SALES estimate 81737866786 (basis mismatch as returned). Entity name returned as 'Morgan Stanley Co.'. Tearsheet source FMP.
A36: MSFT | B36: Microsoft Corp. | C36: Technology | D36: Software | E36: USD | F36: STD | G36: 2026-06-30 | H36: 5 | I36: 331839 | J36: 0.16123979 | K36: 0.17788687 | L36: 0.46780818 | M36: 5 | N36: 66987 | O36: 0.20186597 | P36: 5 | Q36: 5 | R36: 0.24807658 | S36: 0.30233483 | T36: 51965.3 | U36: 0.25041225 | V36: 50.880695 | W36: -0.0025428266 | X36: 0.037382586 | Y36: 30.063889 | Z36: 35.034979 | AA36: =IF(AND(ISNUMBER(Y36),ISNUMBER(Z36),Y36>0,Z36>0),Y36/Z36,"") -> 0.85811065 | AB36: 19.423581 | AC36: 0.016670332 | AD36: 0.17763583 | AE36: Fiscal year ends June 30; provider labels FY ended 2026-06-30 as fiscal_year 2026; estimates fiscal_year 2027 and 2028 are the first two future FYs. Provider capex FY2026 (-115948000000) includes the returned value as-is. fy_market_cap and fy multiples for FY2026 as returned. Provider FMP.
A37: MU | B37: Micron Technology Inc. | C37: Technology | D37: Semiconductors | E37: USD | F37: STD | G37: 2026-09-03 | H37: 5 | I37: 133188 | J37: 1.0464668 | K37: 2.5632725 | L37: 0.75012013 | M37: 4 | N37: 58963 | O37: 0.44270505 | P37: 4 | Q37: 5 | R37: 0.7882957 | S37: 0.61403547 | T37: -38255 | U37: -0.34964811 | V37: 942.51887 | W37: 0.045745654 | X37: 0.010008409 | Y37: 12.553047 | Z37: 14.329388 | AA37: =IF(AND(ISNUMBER(Y37),ISNUMBER(Z37),Y37>0,Z37>0),Y37/Z37,"") -> 0.87603513 | AB37: 9.4825703 | AC37: 0.049415647 | AD37: 1.0808049 | AE37: FY ends ~Sept 3 2026 (53-week). FY2026 figures extremely large vs FY2025 (revenue 133.2B vs 37.4B, EPS 74.33 vs 7.59); copied exactly as returned, not verified against filings.
A38: NFLX | B38: Netflix Inc. | C38: Consumer Services | D38: Entertainment Production | E38: USD | F38: STD | G38: 2025-12-31 | H38: 5 | I38: 45183.036 | J38: 0.12639718 | K38: 0.15851069 | L38: 0.29494705 | M38: 5 | N38: 9461.053 | O38: 0.20939392 | P38: 4 | Q38: 5 | R38: 0.32883645 | S38: 0.41258687 | T38: 5400.477 | U38: 0.17850092 | V38: 17.162178 | W38: -0.043376986 | X38: 0.008154587 | Y38: 22.094427 | Z38: 39.585366 | AA38: =IF(AND(ISNUMBER(Y38),ISNUMBER(Z38),Y38>0,Z38>0),Y38/Z38,"") -> 0.55814634 | AB38: 8.6369421 | AC38: 0.036999004 | AD38: 0.13350504 | AE38: Share counts appear split-adjusted (~10-for-1) in the returned data; TTM key metrics (pe 22.09, ev_to_ebitda 8.64) differ markedly from FY2025 values (36.3, 13.3) - copied as returned.
A39: NOW | B39: ServiceNow Inc. | C39: Technology | D39: Application Software | E39: USD | F39: STD | G39: 2025-12-31 | H39: 5 | I39: 13278 | J39: 0.22376518 | K39: 0.20884924 | L39: 0.13737009 | M39: 5 | N39: 4576 | O39: 0.34463022 | P39: 5 | Q39: 5 | R39: 0.15864362 | S39: 0.13483493 | T39: -3881 | U39: -1.294098 | V39: 79.304348 | W39: 0.028815683 | X39: 0.14723603 | Y39: 88.571429 | Z39: 153.63768 | AA39: =IF(AND(ISNUMBER(Y39),ISNUMBER(Z39),Y39>0,Z39>0),Y39/Z39,"") -> 0.57649548 | AB39: 43.285043 | AC39: 0.031570636 | AD39: 0.2208272 | AE39: Estimate EPS (4.07 for FY2026) not comparable to reported FY2025 EPS 1.67 / shares 1.047B; possible split/basis mismatch in source (not verified). TTM ratios block returned TTM interest_coverage/debt_to_equity differing from FY2025.
... A41: PGR | B41: Progressive Corp. | C41: Financials | D41: Property and Casualty Insurance | E41: USD | F41: FIN | G41: 2025-12-31 | H41: 5 | I41: 87637 | J41: 0.20903783 | K41: 0.16317375 | L41: 0.16229446 | M41: 5 | N41: 17200 | O41: 0.19626414 | P41: 5 | Q41: 5 | R41: 0.64635124 | S41: 0.37291825 | T41: -12939 | U41: -0.87343054 | V41: 51.161871 | W41: 0.0018736161 | X41: 0.0015062131 | Y41: 11.025025 | Z41: 18.040422 | AA41: =IF(AND(ISNUMBER(Y41),ISNUMBER(Z41),Y41>0,Z41>0),Y41/Z41,"") -> 0.61112901 | AB41: 8.9357397 | AC41: 0.12345543 | AD41: 0.0092287457 | AE41: Insurer format: cost_of_revenue 61807000000 FY2025; total_debt is long-term debt only. TTM debt_to_equity 1.709 vs FY2025 0.227; TTM price_to_book 26.16 vs FY2025 4.40; TTM current_ratio 1.600 vs FY2025 0.586 (not comparable). FY2025 cash_and_short_term_investments 19836000000 vs 76090000000 FY2024 as returned. EPS estimate 2026 (18.287) is below FY2025 diluted EPS (19.23); 2027 estimate 16.25884.
...

Sheet Raw_FY
A1: ticker | B1: fiscal_year | C1: report_date | D1: revenue | E1: gross_profit | F1: operating_income | G1: ebitda | H1: net_income | I1: eps_diluted | J1: shares_diluted | K1: interest_expense | L1: operating_cash_flow | M1: capex | N1: free_cash_flow | O1: stock_based_compensation | P1: total_debt | Q1: cash_and_short_term_investments | R1: total_equity | S1: fy_pe_ratio
A2: ABNB | B2: 2025 | C2: 2025-12-31 | D2: 12305000000 | E2: 8892000000 | F2: 2609000000 | G2: 2700000000 | H2: 2511000000 | I2: 4.03 | J2: 623000000 | K2: 0 | L2: 4646000000 | M2: 0 | N2: 4646000000 | O2: 1592000000 | P2: 2271000000 | Q2: 11014000000 | R2: 8199000000 | S2: 33.102439
A3: ABNB | B3: 2024 | C3: 2024-12-31 | D3: 11102000000 | E3: 9224000000 | F3: 2553000000 | G3: 3396000000 | H3: 2648000000 | I3: 4.11 | J3: 645000000 | K3: 0 | L3: 4518000000 | M3: 0 | N3: 4518000000 | O3: 1407000000 | P3: 2294000000 | Q3: 10611000000 | R3: 8412000000 | S3: 31.362768
A4: ABNB | B4: 2023 | C4: 2023-12-31 | D4: 9917000000 | E4: 8214000000 | F4: 1518000000 | G4: 2229000000 | H4: 4792000000 | I4: 7.24 | J4: 662000000 | K4: 83000000 | L4: 3884000000 | M4: 0 | N4: 3884000000 | O4: 1120000000 | P4: 2304000000 | Q4: 10071000000 | R4: 8165000000 | S4: 18.103723
A5: ABNB | B5: 2022 | C5: 2022-12-31 | D5: 8399000000 | E5: 6900000000 | F5: 1802000000 | G5: 1972000000 | H5: 1893000000 | I5: 2.79 | J5: 680000000 | K5: 24000000 | L5: 3430000000 | M5: -25000000 | N5: 3405000000 | O5: 930000000 | P5: 2341000000 | Q5: 9622000000 | R5: 5560000000 | S5: 28.787879
A6: ABNB | B6: 2021 | C6: 2021-12-31 | D6: 5992000000 | E6: 4836000000 | F6: 429000000 | G6: 276000000 | H6: -352000000 | I6: -0.57 | J6: 616000000 | K6: 438000000 | L6: 2313000000 | M6: 0 | N6: 2313000000 | O6: 0 | P6: 2418000000 | Q6: 8322000000 | R6: 4775000000 | S6: -292.08772
